[2025-05-03T05:22:56.295-0300] {local_task_job_runner.py:120} INFO - ::group::Pre task execution logs
[2025-05-03T05:22:56.320-0300] {taskinstance.py:2073} INFO - Dependencies all met for dep_context=non-requeueable deps ti=<TaskInstance: crypto_pipeline.run_etl manual__2025-05-03T08:22:46.880886+00:00 [queued]>
[2025-05-03T05:22:56.325-0300] {taskinstance.py:2073} INFO - Dependencies all met for dep_context=requeueable deps ti=<TaskInstance: crypto_pipeline.run_etl manual__2025-05-03T08:22:46.880886+00:00 [queued]>
[2025-05-03T05:22:56.325-0300] {taskinstance.py:2303} INFO - Starting attempt 1 of 2
[2025-05-03T05:22:56.334-0300] {taskinstance.py:2327} INFO - Executing <Task(BashOperator): run_etl> on 2025-05-03 08:22:46.880886+00:00
[2025-05-03T05:22:56.344-0300] {standard_task_runner.py:63} INFO - Started process 37100 to run task
[2025-05-03T05:22:56.348-0300] {standard_task_runner.py:90} INFO - Running: ['airflow', 'tasks', 'run', 'crypto_pipeline', 'run_etl', 'manual__2025-05-03T08:22:46.880886+00:00', '--job-id', '18', '--raw', '--subdir', 'DAGS_FOLDER/mi_primer_dag.py', '--cfg-path', '/tmp/tmpv1rjpxtp']
[2025-05-03T05:22:56.351-0300] {standard_task_runner.py:91} INFO - Job 18: Subtask run_etl
[2025-05-03T05:22:56.412-0300] {task_command.py:426} INFO - Running <TaskInstance: crypto_pipeline.run_etl manual__2025-05-03T08:22:46.880886+00:00 [running]> on host facuvega
[2025-05-03T05:22:56.519-0300] {taskinstance.py:2644} INFO - Exporting env vars: AIRFLOW_CTX_DAG_OWNER='airflow' AIRFLOW_CTX_DAG_ID='crypto_pipeline' AIRFLOW_CTX_TASK_ID='run_etl' AIRFLOW_CTX_EXECUTION_DATE='2025-05-03T08:22:46.880886+00:00' AIRFLOW_CTX_TRY_NUMBER='1' AIRFLOW_CTX_DAG_RUN_ID='manual__2025-05-03T08:22:46.880886+00:00'
[2025-05-03T05:22:56.521-0300] {taskinstance.py:430} INFO - ::endgroup::
[2025-05-03T05:22:56.523-0300] {subprocess.py:63} INFO - Tmp dir root location: /tmp
[2025-05-03T05:22:56.524-0300] {subprocess.py:75} INFO - Running command: ['/usr/bin/bash', '-c', 'python /home/facuvega/Descargas/crypto-etl-airflow/scripts/etl.py']
[2025-05-03T05:22:56.560-0300] {subprocess.py:86} INFO - Output:
[2025-05-03T05:22:57.859-0300] {subprocess.py:93} INFO - ⏳ Ejecutando ETL...
[2025-05-03T05:22:57.859-0300] {subprocess.py:93} INFO - ✅ Datos validados correctamente
[2025-05-03T05:22:57.860-0300] {subprocess.py:93} INFO - Traceback (most recent call last):
[2025-05-03T05:22:57.860-0300] {subprocess.py:93} INFO -   File "/home/facuvega/Descargas/crypto-etl-airflow/scripts/etl.py", line 102, in <module>
[2025-05-03T05:22:57.860-0300] {subprocess.py:93} INFO -     etl()
[2025-05-03T05:22:57.861-0300] {subprocess.py:93} INFO -   File "/home/facuvega/Descargas/crypto-etl-airflow/scripts/etl.py", line 96, in etl
[2025-05-03T05:22:57.861-0300] {subprocess.py:93} INFO -     dataLoad(crypto_df)
[2025-05-03T05:22:57.861-0300] {subprocess.py:93} INFO -   File "/home/facuvega/Descargas/crypto-etl-airflow/scripts/etl.py", line 49, in dataLoad
[2025-05-03T05:22:57.861-0300] {subprocess.py:93} INFO -     cursor.execute("""
[2025-05-03T05:22:57.861-0300] {subprocess.py:93} INFO - sqlite3.OperationalError: no such table: cryptos
[2025-05-03T05:22:58.003-0300] {subprocess.py:97} INFO - Command exited with return code 1
[2025-05-03T05:22:58.004-0300] {taskinstance.py:441} INFO - ::group::Post task execution logs
[2025-05-03T05:22:58.011-0300] {taskinstance.py:2890} ERROR - Task failed with exception
Traceback (most recent call last):
  File "/home/facuvega/Descargas/crypto-etl-airflow/airflow-apache/lib/python3.11/site-packages/airflow/models/taskinstance.py", line 465, in _execute_task
    result = _execute_callable(context=context, **execute_callable_kwargs)
             ^^^^^^^^^^^^^^^^^^^^^^^^^^^^^^^^^^^^^^^^^^^^^^^^^^^^^^^^^^^^^
  File "/home/facuvega/Descargas/crypto-etl-airflow/airflow-apache/lib/python3.11/site-packages/airflow/models/taskinstance.py", line 432, in _execute_callable
    return execute_callable(context=context, **execute_callable_kwargs)
           ^^^^^^^^^^^^^^^^^^^^^^^^^^^^^^^^^^^^^^^^^^^^^^^^^^^^^^^^^^^^
  File "/home/facuvega/Descargas/crypto-etl-airflow/airflow-apache/lib/python3.11/site-packages/airflow/models/baseoperator.py", line 400, in wrapper
    return func(self, *args, **kwargs)
           ^^^^^^^^^^^^^^^^^^^^^^^^^^^
  File "/home/facuvega/Descargas/crypto-etl-airflow/airflow-apache/lib/python3.11/site-packages/airflow/operators/bash.py", line 243, in execute
    raise AirflowException(
airflow.exceptions.AirflowException: Bash command failed. The command returned a non-zero exit code 1.
[2025-05-03T05:22:58.017-0300] {taskinstance.py:1205} INFO - Marking task as UP_FOR_RETRY. dag_id=crypto_pipeline, task_id=run_etl, execution_date=20250503T082246, start_date=20250503T082256, end_date=20250503T082258
[2025-05-03T05:22:58.033-0300] {standard_task_runner.py:110} ERROR - Failed to execute job 18 for task run_etl (Bash command failed. The command returned a non-zero exit code 1.; 37100)
[2025-05-03T05:22:58.054-0300] {local_task_job_runner.py:240} INFO - Task exited with return code 1
[2025-05-03T05:22:58.077-0300] {taskinstance.py:3482} INFO - 0 downstream tasks scheduled from follow-on schedule check
[2025-05-03T05:22:58.077-0300] {local_task_job_runner.py:222} INFO - ::endgroup::
