[2025-05-06T10:35:51.058-0300] {local_task_job_runner.py:120} INFO - ::group::Pre task execution logs
[2025-05-06T10:35:51.153-0300] {taskinstance.py:2073} INFO - Dependencies all met for dep_context=non-requeueable deps ti=<TaskInstance: crypto_pipeline.run_etl manual__2025-05-06T13:35:39.145633+00:00 [queued]>
[2025-05-06T10:35:51.187-0300] {taskinstance.py:2073} INFO - Dependencies all met for dep_context=requeueable deps ti=<TaskInstance: crypto_pipeline.run_etl manual__2025-05-06T13:35:39.145633+00:00 [queued]>
[2025-05-06T10:35:51.188-0300] {taskinstance.py:2303} INFO - Starting attempt 1 of 2
[2025-05-06T10:35:51.240-0300] {taskinstance.py:2327} INFO - Executing <Task(BashOperator): run_etl> on 2025-05-06 13:35:39.145633+00:00
[2025-05-06T10:35:51.270-0300] {standard_task_runner.py:63} INFO - Started process 65861 to run task
[2025-05-06T10:35:51.286-0300] {standard_task_runner.py:90} INFO - Running: ['airflow', 'tasks', 'run', 'crypto_pipeline', 'run_etl', 'manual__2025-05-06T13:35:39.145633+00:00', '--job-id', '78', '--raw', '--subdir', 'DAGS_FOLDER/mi_primer_dag.py', '--cfg-path', '/tmp/tmp_1d63gyq']
[2025-05-06T10:35:51.291-0300] {standard_task_runner.py:91} INFO - Job 78: Subtask run_etl
[2025-05-06T10:35:51.362-0300] {task_command.py:426} INFO - Running <TaskInstance: crypto_pipeline.run_etl manual__2025-05-06T13:35:39.145633+00:00 [running]> on host facuvega
[2025-05-06T10:35:51.422-0300] {taskinstance.py:2644} INFO - Exporting env vars: AIRFLOW_CTX_DAG_OWNER='airflow' AIRFLOW_CTX_DAG_ID='crypto_pipeline' AIRFLOW_CTX_TASK_ID='run_etl' AIRFLOW_CTX_EXECUTION_DATE='2025-05-06T13:35:39.145633+00:00' AIRFLOW_CTX_TRY_NUMBER='1' AIRFLOW_CTX_DAG_RUN_ID='manual__2025-05-06T13:35:39.145633+00:00'
[2025-05-06T10:35:51.423-0300] {taskinstance.py:430} INFO - ::endgroup::
[2025-05-06T10:35:51.424-0300] {subprocess.py:63} INFO - Tmp dir root location: /tmp
[2025-05-06T10:35:51.425-0300] {subprocess.py:75} INFO - Running command: ['/usr/bin/bash', '-c', 'python /home/facuvega/Descargas/crypto-etl-airflow/scripts/etl.py']
[2025-05-06T10:35:51.450-0300] {subprocess.py:86} INFO - Output:
[2025-05-06T10:35:53.889-0300] {subprocess.py:93} INFO - [DEBUG] DB_PATH absoluto: /home/facuvega/Descargas/crypto-etl-airflow/scripts/db/crypto.db
[2025-05-06T10:35:53.889-0300] {subprocess.py:93} INFO - CreateTable [DEBUG] BASE_DIR: /home/facuvega/Descargas/crypto-etl-airflow/scripts
[2025-05-06T10:35:53.890-0300] {subprocess.py:93} INFO - ✅ Tabla 'cryptos' creada correctamente (si no existía).
[2025-05-06T10:35:53.896-0300] {subprocess.py:93} INFO - ⏳ Ejecutando ETL...
[2025-05-06T10:35:53.896-0300] {subprocess.py:93} INFO - ✅ Datos validados correctamente
[2025-05-06T10:35:53.896-0300] {subprocess.py:93} INFO - ETL [DEBUG] BASE_DIR: /home/facuvega/Descargas/crypto-etl-airflow/scripts
[2025-05-06T10:35:53.896-0300] {subprocess.py:93} INFO - [INFO] La base de datos no existe. Ejecutando createTable.py para crearla.
[2025-05-06T10:35:53.896-0300] {subprocess.py:93} INFO - Traceback (most recent call last):
[2025-05-06T10:35:53.896-0300] {subprocess.py:93} INFO -   File "/home/facuvega/Descargas/crypto-etl-airflow/scripts/etl.py", line 124, in <module>
[2025-05-06T10:35:53.897-0300] {subprocess.py:93} INFO -     etl()
[2025-05-06T10:35:53.897-0300] {subprocess.py:93} INFO -   File "/home/facuvega/Descargas/crypto-etl-airflow/scripts/etl.py", line 118, in etl
[2025-05-06T10:35:53.897-0300] {subprocess.py:93} INFO -     dataLoad(crypto_df)
[2025-05-06T10:35:53.897-0300] {subprocess.py:93} INFO -   File "/home/facuvega/Descargas/crypto-etl-airflow/scripts/etl.py", line 59, in dataLoad
[2025-05-06T10:35:53.897-0300] {subprocess.py:93} INFO -     conn = sqlite3.connect(DB_PATH)
[2025-05-06T10:35:53.897-0300] {subprocess.py:93} INFO -            ^^^^^^^^^^^^^^^^^^^^^^^^
[2025-05-06T10:35:53.897-0300] {subprocess.py:93} INFO - sqlite3.OperationalError: unable to open database file
[2025-05-06T10:35:53.995-0300] {subprocess.py:97} INFO - Command exited with return code 1
[2025-05-06T10:35:53.995-0300] {taskinstance.py:441} INFO - ::group::Post task execution logs
[2025-05-06T10:35:54.002-0300] {taskinstance.py:2890} ERROR - Task failed with exception
Traceback (most recent call last):
  File "/home/facuvega/Descargas/crypto-etl-airflow/airflow-apache/lib/python3.11/site-packages/airflow/models/taskinstance.py", line 465, in _execute_task
    result = _execute_callable(context=context, **execute_callable_kwargs)
             ^^^^^^^^^^^^^^^^^^^^^^^^^^^^^^^^^^^^^^^^^^^^^^^^^^^^^^^^^^^^^
  File "/home/facuvega/Descargas/crypto-etl-airflow/airflow-apache/lib/python3.11/site-packages/airflow/models/taskinstance.py", line 432, in _execute_callable
    return execute_callable(context=context, **execute_callable_kwargs)
           ^^^^^^^^^^^^^^^^^^^^^^^^^^^^^^^^^^^^^^^^^^^^^^^^^^^^^^^^^^^^
  File "/home/facuvega/Descargas/crypto-etl-airflow/airflow-apache/lib/python3.11/site-packages/airflow/models/baseoperator.py", line 400, in wrapper
    return func(self, *args, **kwargs)
           ^^^^^^^^^^^^^^^^^^^^^^^^^^^
  File "/home/facuvega/Descargas/crypto-etl-airflow/airflow-apache/lib/python3.11/site-packages/airflow/operators/bash.py", line 243, in execute
    raise AirflowException(
airflow.exceptions.AirflowException: Bash command failed. The command returned a non-zero exit code 1.
[2025-05-06T10:35:54.007-0300] {taskinstance.py:1205} INFO - Marking task as UP_FOR_RETRY. dag_id=crypto_pipeline, task_id=run_etl, execution_date=20250506T133539, start_date=20250506T133551, end_date=20250506T133554
[2025-05-06T10:35:54.019-0300] {standard_task_runner.py:110} ERROR - Failed to execute job 78 for task run_etl (Bash command failed. The command returned a non-zero exit code 1.; 65861)
[2025-05-06T10:35:54.041-0300] {local_task_job_runner.py:240} INFO - Task exited with return code 1
[2025-05-06T10:35:54.054-0300] {taskinstance.py:3482} INFO - 0 downstream tasks scheduled from follow-on schedule check
[2025-05-06T10:35:54.054-0300] {local_task_job_runner.py:222} INFO - ::endgroup::
